{
 "cells": [
  {
   "cell_type": "code",
   "execution_count": 10,
   "metadata": {},
   "outputs": [
    {
     "ename": "PydanticUserError",
     "evalue": "Cannot create a Pydantic dataclass from DataObject as it is already a Pydantic model\n\nFor further information visit https://errors.pydantic.dev/2.9/u/dataclass-on-model",
     "output_type": "error",
     "traceback": [
      "\u001b[0;31m---------------------------------------------------------------------------\u001b[0m",
      "\u001b[0;31mPydanticUserError\u001b[0m                         Traceback (most recent call last)",
      "Cell \u001b[0;32mIn[10], line 7\u001b[0m\n\u001b[1;32m      5\u001b[0m \u001b[38;5;28;01mimport\u001b[39;00m \u001b[38;5;21;01mpyarrow\u001b[39;00m \u001b[38;5;28;01mas\u001b[39;00m \u001b[38;5;21;01mpa\u001b[39;00m\n\u001b[1;32m      6\u001b[0m \u001b[38;5;28;01mimport\u001b[39;00m \u001b[38;5;21;01mjson\u001b[39;00m\n\u001b[0;32m----> 7\u001b[0m \u001b[38;5;28;01mfrom\u001b[39;00m \u001b[38;5;21;01mdata_object\u001b[39;00m \u001b[38;5;28;01mimport\u001b[39;00m DataObject, ArrowConversionError\n\u001b[1;32m      8\u001b[0m \u001b[38;5;28;01mfrom\u001b[39;00m \u001b[38;5;21;01mtyping\u001b[39;00m \u001b[38;5;28;01mimport\u001b[39;00m List, Dict, Any\n",
      "File \u001b[0;32m~/git/dratos/Beta/beta/data/obj/data_object.py:32\u001b[0m\n\u001b[1;32m     28\u001b[0m \u001b[38;5;28;01mclass\u001b[39;00m \u001b[38;5;21;01mArrowConversionError\u001b[39;00m(DataObjectError):\n\u001b[1;32m     29\u001b[0m \u001b[38;5;250m    \u001b[39m\u001b[38;5;124;03m\"\"\"Raised when conversion to/from Arrow fails.\"\"\"\u001b[39;00m\n\u001b[0;32m---> 32\u001b[0m \u001b[38;5;129;43m@dataclass\u001b[39;49m\n\u001b[1;32m     33\u001b[0m \u001b[38;5;28;43;01mclass\u001b[39;49;00m\u001b[43m \u001b[49m\u001b[38;5;21;43;01mDataObject\u001b[39;49;00m\u001b[43m(\u001b[49m\u001b[43mBaseModel\u001b[49m\u001b[43m)\u001b[49m\u001b[43m:\u001b[49m\n\u001b[1;32m     34\u001b[0m \u001b[38;5;250;43m    \u001b[39;49m\u001b[38;5;124;43;03m\"\"\"\u001b[39;49;00m\n\u001b[1;32m     35\u001b[0m \u001b[38;5;124;43;03m    Base class for all data objects in the system.\u001b[39;49;00m\n\u001b[1;32m     36\u001b[0m \u001b[38;5;124;43;03m    Provides common fields and methods for Arrow conversion and data manipulation.\u001b[39;49;00m\n\u001b[1;32m     37\u001b[0m \u001b[38;5;124;43;03m    \"\"\"\u001b[39;49;00m\n\u001b[1;32m     39\u001b[0m \u001b[43m    \u001b[49m\u001b[43m__tablename__\u001b[49m\u001b[43m:\u001b[49m\u001b[43m \u001b[49m\u001b[43mClassVar\u001b[49m\u001b[43m[\u001b[49m\u001b[38;5;28;43mstr\u001b[39;49m\u001b[43m]\u001b[49m\u001b[43m \u001b[49m\u001b[38;5;241;43m=\u001b[39;49m\u001b[43m \u001b[49m\u001b[38;5;124;43m\"\u001b[39;49m\u001b[38;5;124;43mobjects\u001b[39;49m\u001b[38;5;124;43m\"\u001b[39;49m\n",
      "File \u001b[0;32m~/git/dratos/Beta/.venv/lib/python3.11/site-packages/pydantic/dataclasses.py:264\u001b[0m, in \u001b[0;36mdataclass\u001b[0;34m(_cls, init, repr, eq, order, unsafe_hash, frozen, config, validate_on_init, kw_only, slots)\u001b[0m\n\u001b[1;32m    261\u001b[0m     _pydantic_dataclasses\u001b[38;5;241m.\u001b[39mcomplete_dataclass(\u001b[38;5;28mcls\u001b[39m, config_wrapper, raise_errors\u001b[38;5;241m=\u001b[39m\u001b[38;5;28;01mFalse\u001b[39;00m, types_namespace\u001b[38;5;241m=\u001b[39m\u001b[38;5;28;01mNone\u001b[39;00m)\n\u001b[1;32m    262\u001b[0m     \u001b[38;5;28;01mreturn\u001b[39;00m \u001b[38;5;28mcls\u001b[39m\n\u001b[0;32m--> 264\u001b[0m \u001b[38;5;28;01mreturn\u001b[39;00m create_dataclass \u001b[38;5;28;01mif\u001b[39;00m _cls \u001b[38;5;129;01mis\u001b[39;00m \u001b[38;5;28;01mNone\u001b[39;00m \u001b[38;5;28;01melse\u001b[39;00m \u001b[43mcreate_dataclass\u001b[49m\u001b[43m(\u001b[49m\u001b[43m_cls\u001b[49m\u001b[43m)\u001b[49m\n",
      "File \u001b[0;32m~/git/dratos/Beta/.venv/lib/python3.11/site-packages/pydantic/dataclasses.py:197\u001b[0m, in \u001b[0;36mdataclass.<locals>.create_dataclass\u001b[0;34m(cls)\u001b[0m\n\u001b[1;32m    194\u001b[0m \u001b[38;5;28;01mfrom\u001b[39;00m \u001b[38;5;21;01m.\u001b[39;00m\u001b[38;5;21;01m_internal\u001b[39;00m\u001b[38;5;21;01m.\u001b[39;00m\u001b[38;5;21;01m_utils\u001b[39;00m \u001b[38;5;28;01mimport\u001b[39;00m is_model_class\n\u001b[1;32m    196\u001b[0m \u001b[38;5;28;01mif\u001b[39;00m is_model_class(\u001b[38;5;28mcls\u001b[39m):\n\u001b[0;32m--> 197\u001b[0m     \u001b[38;5;28;01mraise\u001b[39;00m PydanticUserError(\n\u001b[1;32m    198\u001b[0m         \u001b[38;5;124mf\u001b[39m\u001b[38;5;124m'\u001b[39m\u001b[38;5;124mCannot create a Pydantic dataclass from \u001b[39m\u001b[38;5;132;01m{\u001b[39;00m\u001b[38;5;28mcls\u001b[39m\u001b[38;5;241m.\u001b[39m\u001b[38;5;18m__name__\u001b[39m\u001b[38;5;132;01m}\u001b[39;00m\u001b[38;5;124m as it is already a Pydantic model\u001b[39m\u001b[38;5;124m'\u001b[39m,\n\u001b[1;32m    199\u001b[0m         code\u001b[38;5;241m=\u001b[39m\u001b[38;5;124m'\u001b[39m\u001b[38;5;124mdataclass-on-model\u001b[39m\u001b[38;5;124m'\u001b[39m,\n\u001b[1;32m    200\u001b[0m     )\n\u001b[1;32m    202\u001b[0m original_cls \u001b[38;5;241m=\u001b[39m \u001b[38;5;28mcls\u001b[39m\n\u001b[1;32m    204\u001b[0m \u001b[38;5;66;03m# if config is not explicitly provided, try to read it from the type\u001b[39;00m\n",
      "\u001b[0;31mPydanticUserError\u001b[0m: Cannot create a Pydantic dataclass from DataObject as it is already a Pydantic model\n\nFor further information visit https://errors.pydantic.dev/2.9/u/dataclass-on-model"
     ]
    }
   ],
   "source": [
    "import unittest\n",
    "from datetime import datetime, date, time\n",
    "import uuid\n",
    "import ulid\n",
    "import pyarrow as pa\n",
    "import json\n",
    "from data_object import DataObject, ArrowConversionError\n",
    "from typing import List, Dict, Any\n"
   ]
  },
  {
   "cell_type": "code",
   "execution_count": 7,
   "metadata": {},
   "outputs": [],
   "source": []
  },
  {
   "cell_type": "code",
   "execution_count": 8,
   "metadata": {},
   "outputs": [
    {
     "name": "stderr",
     "output_type": "stream",
     "text": [
      "test_create_data_object (__main__.TestDataObject.test_create_data_object) ... ERROR\n",
      "test_from_arrow (__main__.TestDataObject.test_from_arrow) ... ERROR\n",
      "test_from_arrow_batch (__main__.TestDataObject.test_from_arrow_batch) ... ERROR\n",
      "test_from_arrow_table (__main__.TestDataObject.test_from_arrow_table) ... ERROR\n",
      "test_from_json (__main__.TestDataObject.test_from_json) ... ERROR\n",
      "test_get_arrow_schema (__main__.TestDataObject.test_get_arrow_schema) ... ERROR\n",
      "test_invalid_arrow_conversion (__main__.TestDataObject.test_invalid_arrow_conversion) ... ERROR\n",
      "test_to_arrow (__main__.TestDataObject.test_to_arrow) ... ERROR\n",
      "test_to_arrow_batch (__main__.TestDataObject.test_to_arrow_batch) ... ERROR\n",
      "test_to_arrow_table (__main__.TestDataObject.test_to_arrow_table) ... ERROR\n",
      "test_to_dataframe (__main__.TestDataObject.test_to_dataframe) ... ERROR\n",
      "test_to_json (__main__.TestDataObject.test_to_json) ... ERROR\n",
      "test_to_json_schema (__main__.TestDataObject.test_to_json_schema) ... ERROR\n",
      "\n",
      "======================================================================\n",
      "ERROR: test_create_data_object (__main__.TestDataObject.test_create_data_object)\n",
      "----------------------------------------------------------------------\n",
      "Traceback (most recent call last):\n",
      "  File \"/var/folders/3y/zg7vxt8x3093z69km_lm4v5h0000gp/T/ipykernel_3037/126021702.py\", line 3, in setUp\n",
      "    class TestObject(DataObject):\n",
      "     ^^^^^^^^^^\n",
      "NameError: name 'DataObject' is not defined\n",
      "\n",
      "======================================================================\n",
      "ERROR: test_from_arrow (__main__.TestDataObject.test_from_arrow)\n",
      "----------------------------------------------------------------------\n",
      "Traceback (most recent call last):\n",
      "  File \"/var/folders/3y/zg7vxt8x3093z69km_lm4v5h0000gp/T/ipykernel_3037/126021702.py\", line 3, in setUp\n",
      "    class TestObject(DataObject):\n",
      "     ^^^^^^^^^^\n",
      "NameError: name 'DataObject' is not defined\n",
      "\n",
      "======================================================================\n",
      "ERROR: test_from_arrow_batch (__main__.TestDataObject.test_from_arrow_batch)\n",
      "----------------------------------------------------------------------\n",
      "Traceback (most recent call last):\n",
      "  File \"/var/folders/3y/zg7vxt8x3093z69km_lm4v5h0000gp/T/ipykernel_3037/126021702.py\", line 3, in setUp\n",
      "    class TestObject(DataObject):\n",
      "     ^^^^^^^^^^\n",
      "NameError: name 'DataObject' is not defined\n",
      "\n",
      "======================================================================\n",
      "ERROR: test_from_arrow_table (__main__.TestDataObject.test_from_arrow_table)\n",
      "----------------------------------------------------------------------\n",
      "Traceback (most recent call last):\n",
      "  File \"/var/folders/3y/zg7vxt8x3093z69km_lm4v5h0000gp/T/ipykernel_3037/126021702.py\", line 3, in setUp\n",
      "    class TestObject(DataObject):\n",
      "     ^^^^^^^^^^\n",
      "NameError: name 'DataObject' is not defined\n",
      "\n",
      "======================================================================\n",
      "ERROR: test_from_json (__main__.TestDataObject.test_from_json)\n",
      "----------------------------------------------------------------------\n",
      "Traceback (most recent call last):\n",
      "  File \"/var/folders/3y/zg7vxt8x3093z69km_lm4v5h0000gp/T/ipykernel_3037/126021702.py\", line 3, in setUp\n",
      "    class TestObject(DataObject):\n",
      "     ^^^^^^^^^^\n",
      "NameError: name 'DataObject' is not defined\n",
      "\n",
      "======================================================================\n",
      "ERROR: test_get_arrow_schema (__main__.TestDataObject.test_get_arrow_schema)\n",
      "----------------------------------------------------------------------\n",
      "Traceback (most recent call last):\n",
      "  File \"/var/folders/3y/zg7vxt8x3093z69km_lm4v5h0000gp/T/ipykernel_3037/126021702.py\", line 3, in setUp\n",
      "    class TestObject(DataObject):\n",
      "     ^^^^^^^^^^\n",
      "NameError: name 'DataObject' is not defined\n",
      "\n",
      "======================================================================\n",
      "ERROR: test_invalid_arrow_conversion (__main__.TestDataObject.test_invalid_arrow_conversion)\n",
      "----------------------------------------------------------------------\n",
      "Traceback (most recent call last):\n",
      "  File \"/var/folders/3y/zg7vxt8x3093z69km_lm4v5h0000gp/T/ipykernel_3037/126021702.py\", line 3, in setUp\n",
      "    class TestObject(DataObject):\n",
      "     ^^^^^^^^^^\n",
      "NameError: name 'DataObject' is not defined\n",
      "\n",
      "======================================================================\n",
      "ERROR: test_to_arrow (__main__.TestDataObject.test_to_arrow)\n",
      "----------------------------------------------------------------------\n",
      "Traceback (most recent call last):\n",
      "  File \"/var/folders/3y/zg7vxt8x3093z69km_lm4v5h0000gp/T/ipykernel_3037/126021702.py\", line 3, in setUp\n",
      "    class TestObject(DataObject):\n",
      "     ^^^^^^^^^^\n",
      "NameError: name 'DataObject' is not defined\n",
      "\n",
      "======================================================================\n",
      "ERROR: test_to_arrow_batch (__main__.TestDataObject.test_to_arrow_batch)\n",
      "----------------------------------------------------------------------\n",
      "Traceback (most recent call last):\n",
      "  File \"/var/folders/3y/zg7vxt8x3093z69km_lm4v5h0000gp/T/ipykernel_3037/126021702.py\", line 3, in setUp\n",
      "    class TestObject(DataObject):\n",
      "     ^^^^^^^^^^\n",
      "NameError: name 'DataObject' is not defined\n",
      "\n",
      "======================================================================\n",
      "ERROR: test_to_arrow_table (__main__.TestDataObject.test_to_arrow_table)\n",
      "----------------------------------------------------------------------\n",
      "Traceback (most recent call last):\n",
      "  File \"/var/folders/3y/zg7vxt8x3093z69km_lm4v5h0000gp/T/ipykernel_3037/126021702.py\", line 3, in setUp\n",
      "    class TestObject(DataObject):\n",
      "     ^^^^^^^^^^\n",
      "NameError: name 'DataObject' is not defined\n",
      "\n",
      "======================================================================\n",
      "ERROR: test_to_dataframe (__main__.TestDataObject.test_to_dataframe)\n",
      "----------------------------------------------------------------------\n",
      "Traceback (most recent call last):\n",
      "  File \"/var/folders/3y/zg7vxt8x3093z69km_lm4v5h0000gp/T/ipykernel_3037/126021702.py\", line 3, in setUp\n",
      "    class TestObject(DataObject):\n",
      "     ^^^^^^^^^^\n",
      "NameError: name 'DataObject' is not defined\n",
      "\n",
      "======================================================================\n",
      "ERROR: test_to_json (__main__.TestDataObject.test_to_json)\n",
      "----------------------------------------------------------------------\n",
      "Traceback (most recent call last):\n",
      "  File \"/var/folders/3y/zg7vxt8x3093z69km_lm4v5h0000gp/T/ipykernel_3037/126021702.py\", line 3, in setUp\n",
      "    class TestObject(DataObject):\n",
      "     ^^^^^^^^^^\n",
      "NameError: name 'DataObject' is not defined\n",
      "\n",
      "======================================================================\n",
      "ERROR: test_to_json_schema (__main__.TestDataObject.test_to_json_schema)\n",
      "----------------------------------------------------------------------\n",
      "Traceback (most recent call last):\n",
      "  File \"/var/folders/3y/zg7vxt8x3093z69km_lm4v5h0000gp/T/ipykernel_3037/126021702.py\", line 3, in setUp\n",
      "    class TestObject(DataObject):\n",
      "     ^^^^^^^^^^\n",
      "NameError: name 'DataObject' is not defined\n",
      "\n",
      "----------------------------------------------------------------------\n",
      "Ran 13 tests in 0.008s\n",
      "\n",
      "FAILED (errors=13)\n"
     ]
    },
    {
     "data": {
      "text/plain": [
       "<unittest.runner.TextTestResult run=13 errors=13 failures=0>"
      ]
     },
     "execution_count": 8,
     "metadata": {},
     "output_type": "execute_result"
    }
   ],
   "source": [
    "\n",
    "suite = unittest.TestLoader().loadTestsFromTestCase(TestDataObject)\n",
    "\n",
    "# Run the tests\n",
    "unittest.TextTestRunner(verbosity=2).run(suite)"
   ]
  },
  {
   "cell_type": "code",
   "execution_count": null,
   "metadata": {},
   "outputs": [],
   "source": []
  }
 ],
 "metadata": {
  "kernelspec": {
   "display_name": ".venv",
   "language": "python",
   "name": "python3"
  },
  "language_info": {
   "codemirror_mode": {
    "name": "ipython",
    "version": 3
   },
   "file_extension": ".py",
   "mimetype": "text/x-python",
   "name": "python",
   "nbconvert_exporter": "python",
   "pygments_lexer": "ipython3",
   "version": "3.11.6"
  }
 },
 "nbformat": 4,
 "nbformat_minor": 2
}
